2016-03-23 17:20:20 [31670] [INFO] Starting gunicorn 0.13.4
2016-03-23 17:20:20 [31670] [INFO] Listening at: http://0.0.0.0:8000 (31670)
2016-03-23 17:20:20 [31670] [INFO] Using worker: sync
2016-03-23 17:20:20 [31673] [INFO] Booting worker with pid: 31673
2016-03-23 17:20:20 [31673] [ERROR] Exception in worker process:
Traceback (most recent call last):
  File "/usr/lib/pymodules/python2.7/gunicorn/arbiter.py", line 456, in spawn_worker
    worker.init_process()
  File "/usr/lib/pymodules/python2.7/gunicorn/workers/base.py", line 100, in init_process
    self.wsgi = self.app.wsgi()
  File "/usr/lib/pymodules/python2.7/gunicorn/app/base.py", line 101, in wsgi
    self.callable = self.load()
  File "/usr/lib/pymodules/python2.7/gunicorn/app/wsgiapp.py", line 24, in load
    return util.import_app(self.app_uri)
  File "/usr/lib/pymodules/python2.7/gunicorn/util.py", line 241, in import_app
    __import__(module)
ImportError: Import by filename is not supported.
2016-03-23 17:20:20 [31673] [INFO] Worker exiting (pid: 31673)
2016-03-23 17:20:21 [31670] [INFO] Shutting down: Master
2016-03-23 17:20:21 [31670] [INFO] Reason: Worker failed to boot.
